Workbook

Sheet Assumptions
B2: ASSUMPTIONS & CALCULATIONS
B3: Corporate Tax Rate | C3: 0.3
B4: Rf (10Y Government Bond Yeild) | C4: 0.068
B5: Rm (Risk Premium) | C5: 0.0725
B6: Beta | C6: 1.1
B7: Kd (Before tax) | C7: 0.15769267
B8: Market Value of firm's equity (E) | C8: ='Projected Income Statement'!G37 -> 27234
B9: Market Value of firm's debt (D) | C9: 0
B10: V (E+D) | C10: =C8+C9 -> 27234
B12: WACC CALCULATION
B13: E/V | C13: =C8/C10 -> 1
B14: D/V | C14: =C9/C10 -> 0
B15: Kd (Post Tax) | C15: =C7*(1-C3) -> 0.11038487
B16: Ke | C16: =C4+(C6*(C5)) -> 0.14775
B18: WACC | C18: =(C13*C16) + (C14*C15) -> 0.14775

Sheet Cash Flows
B2: Infosys
B3: Consolidated Cash Flow | C3: ------------------- in Rs. Cr. -------------------
C5: Mar 24 | D5: 45352 | E5: 44986 | F5: 44986 | G5: 44621
B6: #VALUE!
C7: 12 mths | D7: 12 mths | E7: 12 mths | F7: 12 mths | G7: 12 mths
B8: #VALUE!
B9: Net Profit/Loss Before Extraordinary Items And Tax | C9: 27234 | D9: 35953 | E9: 0 | F9: 23268 | G9: 21235
B10: Net CashFlow From Operating Activities | C10: 20787 | D10: 20787 | E10: 0 | F10: 19169 | G10: 22096
B11: Net Cash Used In Investing Activities | C11: -3261 | D11: -3261 | E11: 0 | F11: 821 | G11: -3150
B12: Net Cash Used From Financing Activities | C12: -15825 | D12: -15825 | E12: 0 | F12: -25857 | G12: -24275
B13: Foreign Exchange Gains / Losses | C13: -44 | D13: -44 | E13: 0 | F13: 131 | G13: -13
B14: Net Inc/Dec In Cash And Cash Equivalents | C14: 1657 | D14: 1657 | E14: 0 | F14: -5736 | G14: -5342
B15: Cash And Cash Equivalents Begin of Year | C15: 6534 | D15: 6534 | E15: 0 | F15: 12270 | G15: 17612

Sheet DCF
A1: Calculation of PV of FCFF | B1: Consolidated | D1: in cr
B2: 1 | C2: 2 | D2: 3 | E2: 4 | F2: 5 | G2: 6
B3: Mar-24A | C3: Mar-25E | D3: Mar-26E | E3: Mar-27E | F3: Mar-28E | G3: Mar-29E
A4: EBIT | B4: 36230 | C4: =B4*(1+$B$46) -> 40215.3 | D4: =C4*(1+$B$46) -> 44638.983 | E4: =D4*(1+$B$46) -> 49549.271 | F4: =E4*(1+$B$46) -> 54999.691 | G4: =F4*(1+$B$46) -> 61049.657
A5: Tax Rate | B5: 0.3 | C5: 0.3 | D5: 0.3 | E5: 0.3 | F5: 0.3 | G5: 0.3
A6: EBIT(1-tax) | B6: =B4*(1-B5) -> 25361 | C6: =C4*(1-C5) -> 28150.71 | D6: =D4*(1-D5) -> 31247.288 | E6: =E4*(1-E5) -> 34684.49 | F6: =F4*(1-F5) -> 38499.784 | G6: =G4*(1-G5) -> 42734.76
A7: Add: Depreciation | B7: =#REF! -> #REF! | C7: =C4*$B$19 -> #REF! | D7: =D4*$B$19 -> #REF! | E7: =E4*$B$19 -> #REF! | F7: =F4*$B$19 -> #REF! | G7: =G4*$B$19 -> #REF!
A8: Less: Reinvestment Rate | B8: =$B$32 -> #REF! | C8: =$B$32 -> #REF! | D8: =$B$32 -> #REF! | E8: =$B$32 -> #REF! | F8: =$B$32 -> #REF! | G8: =$B$32 -> #REF!
A9: Free Cash Flow to Firm (FCFF) | B9: =SUM(B6:B7)*(1+B8) -> #REF! | C9: =SUM(C6:C7)*(1+C8) -> #REF! | D9: =SUM(D6:D7)*(1+D8) -> #REF! | E9: =SUM(E6:E7)*(1+E8) -> #REF! | F9: =SUM(F6:F7)*(1+F8) -> #REF! | G9: =SUM(G6:G7)*(1+G8) -> #REF!
A11: PV OF FCFF | C11: =C9/(1+$B$55)^C2 -> #REF! | D11: =D9/(1+$B$55)^D2 -> #REF! | E11: =E9/(1+$B$55)^E2 -> #REF! | F11: =F9/(1+$B$55)^F2 -> #REF! | G11: =G9/(1+$B$55)^G2 -> #REF!
A13: Profit Before Depreciation and Tax | B13: 45352 | C13: 44986 | D13: 44621 | E13: Mar-21 | F13: 43891
B14: =#REF! -> #REF! | C14: =#REF! -> #REF! | D14: =#REF! -> #REF! | E14: =#REF! -> #REF! | F14: =#REF! -> #REF!
A15: Depreciation | B15: =#REF! -> #REF! | C15: =#REF! -> #REF! | D15: =#REF! -> #REF! | E15: =#REF! -> #REF! | F15: =#REF! -> #REF!
A16: % Depreciation | B16: =B15/B14 -> #REF! | C16: =C15/C14 -> #REF! | D16: =D15/D14 -> #REF! | E16: =E15/E14 -> #REF! | F16: =F15/F14 -> #REF!
A18: Average | B18: =AVERAGE(B16:F16) -> #REF!
A19: Median | B19: =MEDIAN(B16:F16) -> #REF!
A22: Calculation of Reinvestment Rate | B22: 45352 | C22: 44986 | D22: 44621 | E22: Mar-21 | F22: 43891
A23: Net Capex | B23: 2201 | C23: 2579 | D23: 2161 | E23: 2107 | F23: 3307
A24: Change in Working Capital | B24: =(#REF!-#REF!)-(#REF!-#REF!) -> #REF! | C24: =(#REF!-#REF!)-(#REF!-#REF!) -> #REF! | D24: =(#REF!-#REF!)-(#REF!-#REF!) -> #REF! | E24: =(#REF!-#REF!)-(#REF!-#REF!) -> #REF!
A25: EBIT | B25: =#REF!+#REF! -> #REF! | C25: =#REF!+#REF! -> #REF! | D25: =#REF!+#REF! -> #REF! | E25: =#REF!+#REF! -> #REF!
A26: Tax Rate | B26: 0.3 | C26: 0.3 | D26: 0.3 | E26: 0.3
A27: EBIT(1-tax) | B27: =B25*(1-B26) -> #REF! | C27: =C25*(1-C26) -> #REF! | D27: =D25*(1-D26) -> #REF! | E27: =E25*(1-E26) -> #REF!
A28: Reinvestment | B28: =SUM(B23:B24) -> #REF! | C28: =SUM(C23:C24) -> #REF! | D28: =SUM(D23:D24) -> #REF! | E28: =SUM(E23:E24) -> #REF!
A29: Reinvestment Rate | B29: =B28/B27 -> #REF! | C29: =C28/C27 -> #REF! | D29: =D28/D27 -> #REF! | E29: =E28/E27 -> #REF!
A31: Average | B31: =AVERAGE(B29:E29) -> #REF!
A32: Median | B32: =MEDIAN(B29:E29) -> #REF!
A35: Cost of Debt | D35: Cost of Equity
A36: Pre Tax Cost of Debt | B36: 0.1 | D36: Risk Free Rate | E36: 0.068 | F36: 10y | G36: Rm | H36: 0.1243 | I36: 10yr nift50
A37: Tax Rate | B37: 0.3 | D37: Market Premium | G37: rm-rf | H37: =H36-E36 -> 0.0563
A38: After Tax cost of debt | B38: =B36*(1-B37) -> 0.07 | D38: Levered Beta | E38: 0.7
D39: Cost of Equity | E39: =E36+E38*H37 -> 0.10741
A41: EBIT Margin | B41: =B25/#REF! -> #REF! | C41: =C25/#REF! -> #REF! | D41: =D25/#REF! -> #REF! | E41: =E25/#REF! -> #REF! | F41: =(#REF!+#REF!)/#REF! -> #REF!
A42: Average | B42: =AVERAGE(B41:F41) -> #REF!
A43: Median | B43: =MEDIAN(B41:F41) -> #REF!
A46: Expected growth | B46: 0.11
A49: WACC Schedule | D49: Weights Calculation
A50: Cost of Equity | B50: =E39 -> 0.10741 | D50: Total Debt | E50: 8359
A51: Weight of Equity | B51: =1-B53 -> 0.98655722 | D51: Market Cap | E51: 621821
A52: Cost of Debt | B52: =B38 -> 0.07 | D52: Debt/Equity | E52: =E50/E51 -> 0.013442775
A53: Weight of Debt | B53: =E52 -> 0.013442775
...

Sheet Projected Income Statement
B2: ------------------- in Rs. Cr. -------------------
C3: 43891 | D3: 44256 | E3: 44621 | F3: 44986 | G3: 45352 | I3: 45717 | J3: 46082 | K3: 46447 | L3: 46813 | M3: 47178
B4: INCOME | O4: Notes
B5: Revenue From Operations [Gross] | C5: 79047 | D5: 85912 | E5: 103940 | F5: 124014 | G5: 128933 | I5: =G5*(1+I7) -> 146000.03 | J5: =I5*(1+J7) -> 165326.24 | K5: =J5*(1+K7) -> 187210.7 | L5: =K5*(1+L7) -> 211992.02 | M5: =L5*(1+M7) -> 240053.68
B6: Revenue From Operations [Net] | C6: 79047 | D6: 85912 | E6: 103940 | F6: 124014 | G6: 128933 | I6: =G6*(1+I7) -> 146000.03 | J6: =I6*(1+J7) -> 165326.24 | K6: =J6*(1+K7) -> 187210.7 | L6: =K6*(1+L7) -> 211992.02 | M6: =L6*(1+M7) -> 240053.68
B7: growth in Revenue From Operations [Net] | C7: - | D7: =(D6-C6)/C6 -> 0.086847066 | E7: =(E6-D6)/D6 -> 0.20984263 | F7: =(F6-E6)/E6 -> 0.19313065 | G7: =(G6-F6)/F6 -> 0.039664877 | I7: =AVERAGE(D7:G7) -> 0.13237131 | J7: 0.13237131 | K7: 0.13237131 | L7: 0.13237131 | M7: 0.13237131 | O7: Average of historical growth
B8: Total Operating Revenues | C8: 79047 | D8: 85912 | E8: 103940 | F8: 124014 | G8: 128933 | I8: =I6 -> 146000.03 | J8: =J6 -> 165326.24 | K8: =K6 -> 187210.7 | L8: =L6 -> 211992.02 | M8: =M6 -> 240053.68 | O8: https://simplywall.st/stocks/in/software/nse-infy/infosys-shares
B9: Other Income | C9: 2700 | D9: 2467 | E9: 3224 | F9: 3859 | G9: 7417 | I9: =G9*(1+I10) -> 9900.7956 | J9: =I9*(1+J10) -> 13216.362 | K9: =J9*(1+K10) -> 17642.24 | L9: =K9*(1+L10) -> 23550.251 | M9: =L9*(1+M10) -> 31436.729
B10: growth in other income | C10: - | D10: =(D9-C9)/C9 -> -0.086296296 | E10: =(E9-D9)/D9 -> 0.30685043 | F10: =(F9-E9)/E9 -> 0.1969603 | G10: =(G9-F9)/F9 -> 0.92200052 | I10: =AVERAGE(D10:G10) -> 0.33487874 | J10: 0.33487874 | K10: 0.33487874 | L10: 0.33487874 | M10: 0.33487874 | O10: Average of historical growth
B11: Total Revenue | C11: 81747 | D11: 88379 | E11: 107164 | F11: 127873 | G11: 136350 | I11: =I8+I9 -> 155900.83 | J11: =J8+J9 -> 178542.61 | K11: =K8+K9 -> 204852.94 | L11: =L8+L9 -> 235542.27 | M11: =M8+M9 -> 271490.41
B12: EXPENSES
B13: Operating And Direct Expenses | C13: 13791 | D13: 13533 | E13: 21958 | F13: 27275 | G13: 28449 | I13: =I11*I14 -> 29579.793 | J13: =J11*J14 -> 33875.724 | K13: =K11*K14 -> 38867.705 | L13: =L11*L14 -> 44690.536 | M13: =M11*M14 -> 51511.145
B14: % of revenue | C14: =C13/C11 -> 0.16870344 | D14: =D13/D11 -> 0.15312461 | E14: =E13/E11 -> 0.2049009 | F14: =F13/F11 -> 0.21329757 | G14: =G13/G11 -> 0.20864686 | I14: =AVERAGE(C14:G14) -> 0.18973468 | J14: 0.18973468 | K14: 0.18973468 | L14: 0.18973468 | M14: 0.18973468 | O14: Average of historical % of revenue
B15: Employee Benefit Expenses | C15: 42434 | D15: 45179 | E15: 51664 | F15: 62764 | G15: 65139 | I15: =I16*I11 -> 77356.499 | J15: =J16*J11 -> 88591.134 | K15: =K16*K11 -> 101646.07 | L15: =L16*L11 -> 116873.82 | M15: =M16*M11 -> 134710.95
B16: % of revenue | C16: =C15/$C$11 -> 0.51908939 | D16: =D15/$D$11 -> 0.5111961 | E16: =E15/$E$11 -> 0.4821022 | F16: =F15/$F$11 -> 0.49083075 | G16: =G15/$G$11 -> 0.47773377 | I16: =AVERAGE(C16:G16) -> 0.49619044 | J16: 0.49619044 | K16: 0.49619044 | L16: 0.49619044 | M16: 0.49619044 | O16: Average of historical % of revenue
B17: Finance Costs | C17: 114 | D17: 126 | E17: 128 | F17: 157 | G17: 277 | I17: =I18*I11 -> 226.80367 | J17: =J18*J11 -> 259.74281 | K17: =K18*K11 -> 298.01893 | L17: =L18*L11 -> 342.66561 | M17: =M18*M11 -> 394.96277
B18: % of revenue | C18: =C17/$C$11 -> 0.0013945466 | D18: =D17/$D$11 -> 0.001425678 | E18: =E17/$E$11 -> 0.001194431 | F18: =F17/$F$11 -> 0.0012277807 | G18: =G17/$G$11 -> 0.0020315365 | I18: =AVERAGE(C18:G18) -> 0.0014547946 | J18: 0.0014547946 | K18: 0.0014547946 | L18: 0.0014547946 | M18: 0.0014547946 | O18: Average of historical % of revenue
B19: Depreciation And Amortisation Expenses | C19: 2144 | D19: 2321 | E19: 2429 | F19: 2753 | G19: 2944 | I19: =I20*I11 -> 3687.8657 | J19: =J20*J11 -> 4223.4616 | K19: =K20*K11 -> 4845.8378 | L19: =L20*L11 -> 5571.8003 | M19: =M20*M11 -> 6422.1608
B20: % of revenue | C20: =C19/$C$11 -> 0.026227262 | D20: =D19/$D$11 -> 0.026261895 | E20: =E19/$E$11 -> 0.022666194 | F20: =F19/$F$11 -> 0.021529173 | G20: =G19/$G$11 -> 0.021591492 | I20: =AVERAGE(C20:G20) -> 0.023655203 | J20: 0.023655203 | K20: 0.023655203 | L20: 0.023655203 | M20: 0.023655203 | O20: Average of historical % of revenue
B21: Other Expenses | C21: 2787 | D21: 2743 | E21: 2490 | F21: 3281 | G21: 3588 | I21: =I22*I11 -> 4375.765 | J21: =J22*J11 -> 5011.2659 | K21: =K22*K11 -> 5749.7342 | L21: =L22*L11 -> 6611.1107 | M21: =M22*M11 -> 7620.0894
B22: % of revenue | C22: =C21/$C$11 -> 0.034092994 | D22: =D21/$D$11 -> 0.031036785 | E22: =E21/$E$11 -> 0.023235415 | F22: =F21/$F$11 -> 0.02565827 | G22: =G21/$G$11 -> 0.026314631 | I22: =AVERAGE(C22:G22) -> 0.028067619 | J22: 0.028067619 | K22: 0.028067619 | L22: 0.028067619 | M22: 0.028067619 | O22: Average of historical % of revenue
B23: Cost Of Materials Consumed | C23: 0 | D23: 0 | E23: 0 | F23: 0 | G23: 0 | I23: 0 | J23: 0 | K23: 0 | L23: 0 | M23: 0
B24: Purchase Of Stock-In Trade | C24: 0 | D24: 0 | E24: 0 | F24: 0 | G24: 0 | I24: 0 | J24: 0 | K24: 0 | L24: 0 | M24: 0
B25: Changes In Inventories Of FG,WIP And Stock-In Trade | C25: 0 | D25: 0 | E25: 0 | F25: 0 | G25: 0 | I25: 0 | J25: 0 | K25: 0 | L25: 0 | M25: 0
B26: Total Expenses | C26: 61270 | D26: 63902 | E26: 78669 | F26: 96230 | G26: 100397 | I26: =I21+I19+I17+I15+I13 -> 115226.73 | J26: =J21+J19+J17+J15+J13 -> 131961.33 | K26: =K21+K19+K17+K15+K13 -> 151407.36 | L26: =L21+L19+L17+L15+L13 -> 174089.94 | M26: =M21+M19+M17+M15+M13 -> 200659.3
B27: Profit/Loss Before Exceptional, ExtraOrdinary Items And Tax | C27: 20477 | D27: 24477 | E27: 28495 | F27: 31643 | G27: 35953 | I27: =I11-I26 -> 40674.099 | J27: =J11-J26 -> 46581.278 | K27: =K11-K26 -> 53445.571 | L27: =L11-L26 -> 61452.334 | M27: =M11-M26 -> 70831.105
B28: Profit/Loss Before Tax | C28: 20477 | D28: 24477 | E28: 28495 | F28: 31643 | G28: 35953 | I28: =I27 -> 40674.099 | J28: =J27 -> 46581.278 | K28: =K27 -> 53445.571 | L28: =L27 -> 61452.334 | M28: =M27 -> 70831.105
B29: Tax Expenses-Continued Operations
B30: Current Tax | C30: 5235 | D30: 6013 | E30: 6960 | F30: 8167 | G30: 7306 | I30: =I31*I28 -> 9817.6957 | J30: =J31*J28 -> 11243.539 | K30: =K31*K28 -> 12900.405 | L30: =L31*L28 -> 14833.035 | M30: =M31*M28 -> 17096.832
B31: % of profit | C31: =C30/C28 -> 0.25565268 | D31: =D30/D28 -> 0.24565919 | E31: =E30/E28 -> 0.24425338 | F31: =F30/F28 -> 0.25809816 | G31: =G30/G28 -> 0.20320975 | I31: =AVERAGE(C31:G31) -> 0.24137463 | J31: 0.24137463 | K31: 0.24137463 | L31: 0.24137463 | M31: 0.24137463 | O31: Average of historical % of profit
B32: Deferred Tax | C32: -301 | D32: 416 | E32: 300 | F32: 208 | G32: 1413 | I32: =I33*I28 -> 477.50526 | J32: =J33*J28 -> 546.85427 | K32: =K33*K28 -> 627.43961 | L32: =L33*L28 -> 721.43731 | M32: =M33*M28 -> 831.54209
B33: % of profit | C33: =C32/C28 -> -0.014699419 | D33: =D32/D28 -> 0.016995547 | E33: =E32/E28 -> 0.010528163 | F33: =F32/F28 -> 0.0065733338 | G33: =G32/G28 -> 0.03930131 | I33: =AVERAGE(C33:G33) -> 0.011739787 | J33: 0.011739787 | K33: 0.011739787 | L33: 0.011739787 | M33: 0.011739787 | O33: Average of historical % of profit
B34: Total Tax Expenses | C34: 4934 | D34: 6429 | E34: 7260 | F34: 8375 | G34: 8719 | I34: =I32+I30 -> 10295.201 | J34: =J32+J30 -> 11790.393 | K34: =K32+K30 -> 13527.845 | L34: =L32+L30 -> 15554.472 | M34: =M32+M30 -> 17928.374
B35: Profit/Loss After Tax And Before ExtraOrdinary Items | C35: 15543 | D35: 18048 | E35: 21235 | F35: 23268 | G35: 27234 | I35: =I28-I34 -> 30378.898 | J35: =J28-J34 -> 34790.885 | K35: =K28-K34 -> 39917.726 | L35: =L28-L34 -> 45897.862 | M35: =M28-M34 -> 52902.731
B36: Profit/Loss From Continuing Operations | C36: 15543 | D36: 18048 | E36: 21235 | F36: 23268 | G36: 27234 | I36: =I35 -> 30378.898 | J36: =J35 -> 34790.885 | K36: =K35 -> 39917.726 | L36: =L35 -> 45897.862 | M36: =M35 -> 52902.731
B37: Profit/Loss For The Period | C37: 15543 | D37: 18048 | E37: 21235 | F37: 23268 | G37: 27234 | I37: =I36 -> 30378.898 | J37: =J36 -> 34790.885 | K37: =K36 -> 39917.726 | L37: =L36 -> 45897.862 | M37: =M36 -> 52902.731
B38: OTHER ADDITIONAL INFORMATION
B39: EARNINGS PER SHARE
B40: Basic EPS (Rs.) | C40: 36.34 | D40: 42.37 | E40: 50.27 | F40: 55.48 | G40: 65.62 | I40: =I37*5/'Projected Balane Sheet'!$G$6 -> 73.343549 | J40: =J37*5/'Projected Balane Sheet'!$G$6 -> 83.995376 | K40: =K37*5/'Projected Balane Sheet'!$G$6 -> 96.373071 | L40: =L37*5/'Projected Balane Sheet'!$G$6 -> 110.81087 | M40: =M37*5/'Projected Balane Sheet'!$G$6 -> 127.72267 | O40: Face value | P40: 5
B41: Diluted EPS (Rs.) | C41: 36.32 | D41: 42.33 | E41: 50.21 | F41: 55.42 | G41: 65.56 | I41: =I40 -> 73.343549 | J41: =J40 -> 83.995376 | K41: =K40 -> 96.373071 | L41: =L40 -> 110.81087 | M41: =M40 -> 127.72267

Sheet Projected Balane Sheet
B2: ------------------- in Rs. Cr. -------------------
C3: 43891 | D3: 44256 | E3: 44621 | F3: 44986 | G3: 45352 | I3: 45717 | J3: 46082 | K3: 46447 | L3: 46813 | M3: 47178
B4: EQUITIES AND LIABILITIES | O4: Notes
B5: SHAREHOLDER'S FUNDS
B6: Equity Share Capital | C6: 2122 | D6: 2124 | E6: 2098 | F6: 2069 | G6: 2071 | I6: 2071 | J6: 2071 | K6: 2071 | L6: 2071 | M6: 2071
B7: Total Share Capital | C7: 2122 | D7: 2124 | E7: 2098 | F7: 2069 | G7: 2071 | I7: =I6 -> 2071 | J7: =J6 -> 2071 | K7: =K6 -> 2071 | L7: =L6 -> 2071 | M7: =M6 -> 2071
B8: Reserves and Surplus | C8: 63031 | D8: 73855 | E8: 72646 | F8: 72460 | G8: 86045 | I8: =G8*(1+I9) -> 93364.794 | J8: =I8*(1+J9) -> 101307.28 | K8: =J8*(1+K9) -> 109925.43 | L8: =K8*(1+L9) -> 119276.71 | M8: =L8*(1+M9) -> 129423.51
B9: growth in reserves and surplus | C9: - | D9: =(D8-C8)/C8 -> 0.17172502 | E9: =(E8-D8)/D8 -> -0.016369914 | F9: =(F8-E8)/E8 -> -0.0025603612 | G9: =(G8-F8)/F8 -> 0.18748275 | I9: =AVERAGE(D9:G9) -> 0.085069375 | J9: 0.085069375 | K9: 0.085069375 | L9: 0.085069375 | M9: 0.085069375 | O9: Average of historical growth in R&S
B10: Total Reserves and Surplus | C10: 63031 | D10: 73855 | E10: 72646 | F10: 72460 | G10: 86045 | I10: =I8 -> 93364.794 | J10: =J8 -> 101307.28 | K10: =K8 -> 109925.43 | L10: =L8 -> 119276.71 | M10: =M8 -> 129423.51
B11: Employees Stock Options | C11: 297 | D11: 372 | E11: 606 | F11: 878 | G11: 0 | I11: 0 | J11: 0 | K11: 0 | L11: 0 | M11: 0 | O11: Assuming no esops
B12: Total Shareholders Funds | C12: 65450 | D12: 76351 | E12: 75350 | F12: 75407 | G12: 88116 | I12: =I10+I7 -> 95435.794 | J12: =J10+J7 -> 103378.28 | K12: =K10+K7 -> 111996.43 | L12: =L10+L7 -> 121347.71 | M12: =M10+M7 -> 131494.51
B13: NON-CURRENT LIABILITIES
B14: Deferred Tax Liabilities [Net] | C14: 968 | D14: 875 | E14: 1156 | F14: 1220 | G14: 1794 | I14: =I15*'Projected Income Statement'!I28 -> 1724.9277 | J14: =J15*'Projected Income Statement'!J28 -> 1975.4423 | K14: =K15*'Projected Income Statement'!K28 -> 2266.5467 | L14: =L15*'Projected Income Statement'!L28 -> 2606.1016 | M14: =M15*'Projected Income Statement'!M28 -> 3003.8413
B15: % of profit | C15: =C14/'Projected Income Statement'!C28 -> 0.04727255 | D15: =D14/'Projected Income Statement'!D28 -> 0.035747845 | E15: =E14/'Projected Income Statement'!E28 -> 0.040568521 | F15: =F14/'Projected Income Statement'!F28 -> 0.038555131 | G15: =G14/'Projected Income Statement'!G28 -> 0.049898479 | I15: =AVERAGE(C15:G15) -> 0.042408505 | J15: 0.042408505 | K15: 0.042408505 | L15: 0.042408505 | M15: 0.042408505 | O15: Average of historical % of profit
B16: Other Long Term Liabilities | C16: 5100 | D16: 6864 | E16: 7390 | F16: 9615 | G16: 8765 | I16: =I17*'Projected Income Statement'!I28 -> 10872.019 | J16: =J17*'Projected Income Statement'!J28 -> 12450.983 | K16: =K17*'Projected Income Statement'!K28 -> 14285.78 | L16: =L17*'Projected Income Statement'!L28 -> 16425.955 | M16: =M17*'Projected Income Statement'!M28 -> 18932.862
B17: % of profit | C17: =C16/'Projected Income Statement'!C28 -> 0.24905992 | D17: =D16/'Projected Income Statement'!D28 -> 0.28042652 | E17: =E16/'Projected Income Statement'!E28 -> 0.25934374 | F17: =F16/'Projected Income Statement'!F28 -> 0.30385867 | G17: =G16/'Projected Income Statement'!G28 -> 0.2437905 | I17: =AVERAGE(C17:G17) -> 0.26729587 | J17: 0.26729587 | K17: 0.26729587 | L17: 0.26729587 | M17: 0.26729587 | O17: Average of historical % of profit
B18: Total Non-Current Liabilities | C18: 6068 | D18: 7739 | E18: 8546 | F18: 10835 | G18: 10559 | I18: =I16+I14 -> 12596.947 | J18: =J16+J14 -> 14426.426 | K18: =K16+K14 -> 16552.327 | L18: =L16+L14 -> 19032.057 | M18: =M16+M14 -> 21936.703
B19: CURRENT LIABILITIES
B20: Trade Payables | C20: 2852 | D20: 2645 | E20: 4134 | F20: 3865 | G20: 3956 | I20: =I21*'Projected Income Statement'!I11 -> 5070.8711 | J20: =J21*'Projected Income Statement'!J11 -> 5807.3236 | K20: =K21*'Projected Income Statement'!K11 -> 6663.1003 | L20: =L21*'Projected Income Statement'!L11 -> 7661.3097 | M20: =M21*'Projected Income Statement'!M11 -> 8830.5683
B21: % of revenue | C21: =C20/'Projected Income Statement'!C11 -> 0.03488813 | D21: =D20/'Projected Income Statement'!D11 -> 0.029927924 | E21: =E20/'Projected Income Statement'!E11 -> 0.038576388 | F21: =F20/'Projected Income Statement'!F11 -> 0.030225302 | G21: =G20/'Projected Income Statement'!G11 -> 0.029013568 | I21: =AVERAGE(C21:G21) -> 0.032526262 | J21: 0.032526262 | K21: 0.032526262 | L21: 0.032526262 | M21: 0.032526262 | O21: Average of historical % of revenue
B22: Other Current Liabilities | C22: 17432 | D22: 20507 | E22: 28494 | F22: 34014 | G22: 33042 | I22: =I23*'Projected Income Statement'!I11 -> 38024.215 | J22: =J23*'Projected Income Statement'!J11 -> 43546.546 | K22: =K23*'Projected Income Statement'!K11 -> 49963.636 | L22: =L23*'Projected Income Statement'!L11 -> 57448.765 | M22: =M23*'Projected Income Statement'!M11 -> 66216.517
B23: % of revenue | C23: =C22/'Projected Income Statement'!C11 -> 0.2132433 | D23: =D22/'Projected Income Statement'!D11 -> 0.23203476 | E23: =E22/'Projected Income Statement'!E11 -> 0.26589153 | F23: =F22/'Projected Income Statement'!F11 -> 0.2659983 | G23: =G22/'Projected Income Statement'!G11 -> 0.24233223 | I23: =AVERAGE(C23:G23) -> 0.24390002 | J23: 0.24390002 | K23: 0.24390002 | L23: 0.24390002 | M23: 0.24390002 | O23: Average of historical % of revenue
B24: Short Term Provisions | C24: 572 | D24: 713 | E24: 975 | F24: 1307 | G24: 1796 | I24: =I25*'Projected Income Statement'!I11 -> 1482.8037 | J24: =J25*'Projected Income Statement'!J11 -> 1698.1542 | K24: =K25*'Projected Income Statement'!K11 -> 1948.397 | L24: =L25*'Projected Income Statement'!L11 -> 2240.2893 | M24: =M25*'Projected Income Statement'!M11 -> 2582.1992
B25: % of revenue | C25: =C24/'Projected Income Statement'!C11 -> 0.0069971987 | D25: =D24/'Projected Income Statement'!D11 -> 0.0080675274 | E25: =E24/'Projected Income Statement'!E11 -> 0.0090982046 | F25: =F24/'Projected Income Statement'!F11 -> 0.010221079 | G25: =G24/'Projected Income Statement'!G11 -> 0.013171984 | I25: =AVERAGE(C25:G25) -> 0.0095111986 | J25: 0.0095111986 | K25: 0.0095111986 | L25: 0.0095111986 | M25: 0.0095111986 | O25: Average of historical % of revenue
B26: Total Current Liabilities | C26: 20856 | D26: 23865 | E26: 33603 | F26: 39186 | G26: 38794 | I26: =I24+I22+I20 -> 44577.89 | J26: =J24+J22+J20 -> 51052.024 | K26: =K24+K22+K20 -> 58575.133 | L26: =L24+L22+L20 -> 67350.364 | M26: =M24+M22+M20 -> 77629.285
B27: Total Capital And Liabilities | C27: 92768 | D27: 108386 | E27: 117885 | F27: 125816 | G27: 137814 | I27: =I26+I18+I12 -> 152610.63 | J27: =J26+J18+J12 -> 168856.73 | K27: =K26+K18+K12 -> 187123.89 | L27: =L26+L18+L12 -> 207730.13 | M27: =M26+M18+M12 -> 231060.5
B28: ASSETS
B29: NON-CURRENT ASSETS
B30: Tangible Assets | C30: 16603 | D30: 17354 | E30: 17898 | F30: 20228 | G30: 18922 | I30: =I31*'Projected Income Statement'!I11 -> 21635.17 | J30: =J31*'Projected Income Statement'!J11 -> 24777.288 | K30: =K31*'Projected Income Statement'!K11 -> 28428.509 | L30: =L31*'Projected Income Statement'!L11 -> 32687.428 | M30: =M31*'Projected Income Statement'!M11 -> 37676.139
B31: % of revenue | C31: =C30/'Projected Income Statement'!C11 -> 0.20310225 | D31: =D30/'Projected Income Statement'!D11 -> 0.19635886 | E31: =E30/'Projected Income Statement'!E11 -> 0.16701504 | F31: =F30/'Projected Income Statement'!F11 -> 0.1581882 | G31: =G30/'Projected Income Statement'!G11 -> 0.13877521 | I31: 0.13877521 | J31: 0.13877521 | K31: 0.13877521 | L31: 0.13877521 | M31: 0.13877521 | O31: Average of historical % of revenue
B32: Intangible Assets | C32: 1900 | D32: 2072 | E32: 1707 | F32: 1749 | G32: 1397 | I32: =I33*'Projected Income Statement'!I11 -> 2698.3037 | J32: =J33*'Projected Income Statement'!J11 -> 3090.1836 | K32: =K33*'Projected Income Statement'!K11 -> 3545.558 | L32: =L33*'Projected Income Statement'!L11 -> 4076.7236 | M32: =M33*'Projected Income Statement'!M11 -> 4698.9076
B33: % of revenue | C33: =C32/'Projected Income Statement'!C11 -> 0.023242443 | D33: =D32/'Projected Income Statement'!D11 -> 0.023444483 | E33: =E32/'Projected Income Statement'!E11 -> 0.015928857 | F33: =F32/'Projected Income Statement'!F11 -> 0.013677633 | G33: =G32/'Projected Income Statement'!G11 -> 0.010245691 | I33: =AVERAGE(C33:G33) -> 0.017307822 | J33: 0.017307822 | K33: 0.017307822 | L33: 0.017307822 | M33: 0.017307822 | O33: Average of historical % of revenue
B34: Capital Work-In-Progress | C34: 954 | D34: 922 | E34: 416 | F34: 288 | G34: 293 | I34: =I35*'Projected Income Statement'!I11 -> 947.42529 | J34: =J35*'Projected Income Statement'!J11 -> 885.30215 | K34: =K35*'Projected Income Statement'!K11 -> 791.49486 | L34: =L35*'Projected Income Statement'!L11 -> 909.21358 | M34: =M35*'Projected Income Statement'!M11 -> 1135.2798
B35: % of revenue | C35: =C34/'Projected Income Statement'!C11 -> 0.011670153 | D35: =D34/'Projected Income Statement'!D11 -> 0.010432343 | E35: =E34/'Projected Income Statement'!E11 -> 0.0038819006 | F35: =F34/'Projected Income Statement'!F11 -> 0.0022522346 | G35: =G34/'Projected Income Statement'!G11 -> 0.0021488816 | I35: =AVERAGE(C35:G35) -> 0.0060771025 | J35: =AVERAGE(D35:I35) -> 0.0049584924 | K35: =AVERAGE(E35:J35) -> 0.0038637223 | L35: =AVERAGE(F35:K35) -> 0.0038600867 | M35: =AVERAGE(G35:L35) -> 0.0041816571 | O35: Average of historical % of revenue
B36: Fixed Assets | C36: 19457 | D36: 20348 | E36: 20021 | F36: 22265 | G36: 20612 | I36: =I34+I32+I30 -> 25280.899 | J36: =J34+J32+J30 -> 28752.773 | K36: =K34+K32+K30 -> 32765.562 | L36: =L34+L32+L30 -> 37673.365 | M36: =M34+M32+M30 -> 43510.326
B37: Non-Current Investments | C37: 4137 | D37: 11863 | E37: 13651 | F37: 12569 | G37: 11708 | I37: =I38*'Projected Income Statement'!I11 -> 15477.222 | J37: =J38*'Projected Income Statement'!J11 -> 17725.009 | K37: =K38*'Projected Income Statement'!K11 -> 20336.995 | L37: =L38*'Projected Income Statement'!L11 -> 23383.712 | M37: =M38*'Projected Income Statement'!M11 -> 26952.502
B38: % of revenue | C38: =C37/'Projected Income Statement'!C11 -> 0.050607362 | D38: =D37/'Projected Income Statement'!D11 -> 0.13422872 | E38: =E37/'Projected Income Statement'!E11 -> 0.1273842 | F38: =F37/'Projected Income Statement'!F11 -> 0.098292837 | G38: =G37/'Projected Income Statement'!G11 -> 0.085867253 | I38: =AVERAGE((C38:G38)) -> 0.099276074 | J38: 0.099276074 | K38: 0.099276074 | L38: 0.099276074 | M38: 0.099276074 | O38: Average of historical % of revenue
B39: Deferred Tax Assets [Net] | C39: 1744 | D39: 1098 | E39: 1212 | F39: 1245 | G39: 454 | I39: =I40*'Projected Income Statement'!I11 -> 1812.6133 | J39: =J40*'Projected Income Statement'!J11 -> 2075.8627 | K39: =K40*'Projected Income Statement'!K11 -> 2381.7652 | L39: =L40*'Projected Income Statement'!L11 -> 2738.5812 | M39: =M40*'Projected Income Statement'!M11 -> 3156.5397
B40: % of revenue | C40: =C39/'Projected Income Statement'!C11 -> 0.021334116 | D40: =D39/'Projected Income Statement'!D11 -> 0.012423766 | E40: =E39/'Projected Income Statement'!E11 -> 0.011309768 | F40: =F39/'Projected Income Statement'!F11 -> 0.0097362227 | G40: =G39/'Projected Income Statement'!G11 -> 0.0033296663 | I40: =AVERAGE((C40:G40)) -> 0.011626708 | J40: 0.011626708 | K40: 0.011626708 | L40: 0.011626708 | M40: 0.011626708 | O40: Average of historical % of revenue
B41: Long Term Loans And Advances | C41: 21 | D41: 32 | E41: 34 | F41: 39 | G41: 34 | I41: =I42*'Projected Income Statement'!I11 -> 46.476725 | J41: =J42*'Projected Income Statement'!J11 -> 53.22663 | K41: =K42*'Projected Income Statement'!K11 -> 61.070193 | L41: =L42*'Projected Income Statement'!L11 -> 70.219213 | M41: =M42*'Projected Income Statement'!M11 -> 80.935973
...

Sheet FCFF
B2: PARTICULARS | C2: 43891 | D2: 44256 | E2: 44621 | F2: 44986 | G2: 45352 | I2: 45717 | J2: 46082 | K2: 46447 | L2: 46813 | M2: 47178
B3: Profit/(Loss) for the period | C3: ='Projected Income Statement'!C37 -> 15543 | D3: ='Projected Income Statement'!D37 -> 18048 | E3: ='Projected Income Statement'!E37 -> 21235 | F3: ='Projected Income Statement'!F37 -> 23268 | G3: ='Projected Income Statement'!G37 -> 27234 | I3: ='Projected Income Statement'!I37 -> 30378.898 | J3: ='Projected Income Statement'!J37 -> 34790.885 | K3: ='Projected Income Statement'!K37 -> 39917.726 | L3: ='Projected Income Statement'!L37 -> 45897.862 | M3: ='Projected Income Statement'!M37 -> 52902.731
B4: Depreciation And Amortisation Expenses | C4: ='Projected Income Statement'!C19 -> 2144 | D4: ='Projected Income Statement'!D19 -> 2321 | E4: ='Projected Income Statement'!E19 -> 2429 | F4: ='Projected Income Statement'!F19 -> 2753 | G4: ='Projected Income Statement'!G19 -> 2944 | I4: ='Projected Income Statement'!I19 -> 3687.8657 | J4: ='Projected Income Statement'!J19 -> 4223.4616 | K4: ='Projected Income Statement'!K19 -> 4845.8378 | L4: ='Projected Income Statement'!L19 -> 5571.8003 | M4: ='Projected Income Statement'!M19 -> 6422.1608
B5: Deferred Tax | C5: ='Projected Income Statement'!C32 -> -301 | D5: ='Projected Income Statement'!D32 -> 416 | E5: ='Projected Income Statement'!E32 -> 300 | F5: ='Projected Income Statement'!F32 -> 208 | G5: ='Projected Income Statement'!G32 -> 1413 | I5: ='Projected Income Statement'!I32 -> 477.50526 | J5: ='Projected Income Statement'!J32 -> 546.85427 | K5: ='Projected Income Statement'!K32 -> 627.43961 | L5: ='Projected Income Statement'!L32 -> 721.43731 | M5: ='Projected Income Statement'!M32 -> 831.54209
B6: Finance Costs | C6: ='Projected Income Statement'!C17 -> 114 | D6: ='Projected Income Statement'!D17 -> 126 | E6: ='Projected Income Statement'!E17 -> 128 | F6: ='Projected Income Statement'!F17 -> 157 | G6: ='Projected Income Statement'!G17 -> 277 | I6: ='Projected Income Statement'!I17 -> 226.80367 | J6: ='Projected Income Statement'!J17 -> 259.74281 | K6: ='Projected Income Statement'!K17 -> 298.01893 | L6: ='Projected Income Statement'!L17 -> 342.66561 | M6: ='Projected Income Statement'!M17 -> 394.96277
B7: Changes In Inventories Of FG,WIP And Stock-In Trade | C7: ='Projected Income Statement'!C25 -> 0 | D7: ='Projected Income Statement'!D25 -> 0 | E7: ='Projected Income Statement'!E25 -> 0 | F7: ='Projected Income Statement'!F25 -> 0 | G7: ='Projected Income Statement'!G25 -> 0 | H7: ='Projected Income Statement'!H25 -> 0 | I7: ='Projected Income Statement'!I25 -> 0 | J7: ='Projected Income Statement'!J25 -> 0 | ... M7: ='Projected Income Statement'!M25 -> 0
B8: Cost Of Materials Consumed | C8: ='Projected Income Statement'!C23 -> 0 | D8: ='Projected Income Statement'!D23 -> 0 | E8: ='Projected Income Statement'!E23 -> 0 | F8: ='Projected Income Statement'!F23 -> 0 | G8: ='Projected Income Statement'!G23 -> 0 | H8: ='Projected Income Statement'!H23 -> 0 | I8: ='Projected Income Statement'!I23 -> 0 | J8: ='Projected Income Statement'!J23 -> 0 | ... M8: ='Projected Income Statement'!M23 -> 0
B9: Purchase Of Stock-In Trade | C9: ='Projected Income Statement'!C24 -> 0 | D9: ='Projected Income Statement'!D24 -> 0 | E9: ='Projected Income Statement'!E24 -> 0 | F9: ='Projected Income Statement'!F24 -> 0 | G9: ='Projected Income Statement'!G24 -> 0 | H9: ='Projected Income Statement'!H24 -> 0 | I9: ='Projected Income Statement'!I24 -> 0 | J9: ='Projected Income Statement'!J24 -> 0 | ... M9: ='Projected Income Statement'!M24 -> 0
B10: Change in CapEx | D10: =(D8+D9)-(C8+C9) -> 0 | E10: =(E8+E9)-(D8+D9) -> 0 | F10: =(F8+F9)-(E8+E9) -> 0 | G10: =(G8+G9)-(F8+F9) -> 0 | I10: =(I8+I9)-(G8+G9) -> 0 | J10: =(J8+J9)-(I8+I9) -> 0 | K10: =(K8+K9)-(J8+J9) -> 0 | L10: =(L8+L9)-(K8+K9) -> 0 | M10: =(M8+M9)-(L8+L9) -> 0
B12: Year | G12: 0 | I12: 1 | J12: 2 | K12: 3 | L12: 4 | M12: 5
B13: FCFF | D13: =D3+D4+D5+D6-D7-D10 -> 20911 | E13: =E3+E4+E5+E6-E7-E10 -> 24092 | F13: =F3+F4+F5+F6-F7-F10 -> 26386 | G13: =G3+G4+G5+G6-G7-G10 -> 31868 | I13: =I3+I4+I5+I6-I7-I10 -> 34771.073 | J13: =J3+J4+J5+J6-J7-J10 -> 39820.943 | K13: =K3+K4+K5+K6-K7-K10 -> 45689.023 | L13: =L3+L4+L5+L6-L7-L10 -> 52533.766 | M13: =M3+M4+M5+M6-M7-M10 -> 60551.397
B14: FCFE | D14: =D13-D6 -> 20785 | E14: =E13-E6 -> 23964 | F14: =F13-F6 -> 26229 | G14: =G13-G6 -> 31591 | I14: =I13-I6 -> 34544.269 | J14: =J13-J6 -> 39561.201 | K14: =K13-K6 -> 45391.004 | L14: =L13-L6 -> 52191.1 | M14: =M13-M6 -> 60156.434
B15: PV of FCFE | I15: 31039.712 | J15: 31941.316 | K15: 32930.233 | L15: 34022.258 | M15: 35236.312 | O15: Total | P15: =SUM(I15:M15) -> 165169.83
B17: Terminal Value | C17: =(M15*(1+'Projected Income Statement'!I7))/(Assumptions!C18-'Projected Income Statement'!I7) -> 2594536.9

Sheet Peers Comparables
B3: FY 2024 | C3: ------------------- in Rs. Cr. -------------------
C4: Infosys | D4: TCS | E4: Wipro | F4: HCL Tech | G4: Tech Mahindra
B5: INCOME
B6: Revenue From Operations [Gross] | C6: 128933 | D6: 202358 | E6: 66792.2 | F6: 48118 | G6: 42099.3
B7: Revenue From Operations [Net] | C7: 128933 | D7: 202358 | E7: 66792.2 | F7: 48118 | G7: 42099.3
B8: Total Operating Revenues | C8: 128933 | D8: 202358 | E8: 66792.2 | F8: 48118 | G8: 42099.3
B9: Other Income | C9: 7417 | D9: 7273 | E9: 3045.8 | F9: 1076 | G9: 1252.3
B10: Total Revenue | C10: =C8+C9 -> 136350 | D10: =D8+D9 -> 209631 | E10: =E8+E9 -> 69838 | F10: =F8+F9 -> 49194 | G10: =G8+G9 -> 43351.6
B11: EXPENSES
B12: Operating And Direct Expenses | C12: 28449 | D12: 3347 | E12: 13148.5 | F12: 7105 | G12: 16688.6
B13: % of revenue | C13: =C12/C10 -> 0.20864686 | D13: =D12/D10 -> 0.01596615 | E13: =E12/E10 -> 0.18827143 | F13: =F12/F10 -> 0.14442818 | G13: =G12/G10 -> 0.38495926
B14: Employee Benefit Expenses | C14: 65139 | D14: 103139 | E14: 38289.5 | F14: 20965 | G14: 16082.6
B15: % of revenue | C15: =C14/C10 -> 0.47773377 | D15: =D14/D10 -> 0.49200261 | E15: =E14/E10 -> 0.54826169 | F15: =F14/F10 -> 0.42616986 | G15: =G14/G10 -> 0.37098054
B16: Finance Costs | C16: 277 | D16: 673 | E16: 819.7 | F16: 125 | G16: 246.4
B17: % of revenue | C17: =C16/C10 -> 0.0020315365 | D17: =D16/D10 -> 0.003210403 | E17: =E16/E10 -> 0.011737163 | F17: =F16/F10 -> 0.0025409603 | G17: =G16/G10 -> 0.0056837579
B18: Depreciation And Amortisation Expenses | C18: 2944 | D18: 3887 | E18: 1491.8 | F18: 2371 | G18: 814.9
B19: % of revenue | C19: =C18/C10 -> 0.021591492 | D19: =D18/D10 -> 0.018542105 | E19: =E18/E10 -> 0.021360864 | F19: =F18/F10 -> 0.048196935 | G19: =G18/G10 -> 0.018797461
B20: Other Expenses | C20: 3588 | D20: 40026 | E20: 3389.1 | F20: 3027 | G20: 6661.8
B21: % of revenue | C21: =C20/C10 -> 0.026314631 | D21: =D20/D10 -> 0.1909355 | E21: =E20/E10 -> 0.048528022 | F21: =F20/F10 -> 0.061531894 | G21: =G20/G10 -> 0.15366907
B22: Total Expenses | C22: 100397 | D22: 151072 | E22: 57420.7 | F22: 33738 | G22: 40787.1
B23: Profit/Loss Before Exceptional, ExtraOrdinary Items And Tax | C23: 35953 | D23: 58560 | E23: 12417.5 | F23: 15456 | G23: 2564.7
B24: Profit/Loss Before Tax | C24: 35953 | D24: 57602 | E24: 12417.5 | F24: 15456 | G24: 2564.7
B25: Tax Expenses-Continued Operations
B26: Current Tax | C26: 7306 | D26: 14178 | E26: 3148.5 | F26: 2873 | G26: 622.9
B27: % of profit | C27: =C26/C24 -> 0.20320975 | D27: =D26/D24 -> 0.24613729 | E27: =E26/E24 -> 0.25355345 | F27: =F26/F24 -> 0.18588251 | G27: =G26/G24 -> 0.24287441
B28: Deferred Tax | C28: 1413 | D28: -135 | E28: 150.4 | F28: 909 | G28: -186.8
B29: % of profit | C29: =C28/C24 -> 0.03930131 | D29: =D28/D24 -> -0.0023436686 | E29: =E28/E24 -> 0.012111939 | F29: =F28/F24 -> 0.058812112 | G29: =G28/G24 -> -0.072835029
B30: Total Tax Expenses | C30: 8719 | D30: 14043 | E30: 3298.9 | F30: 3782 | G30: 436.1
B31: Profit/Loss After Tax And Before ExtraOrdinary Items | C31: 27234 | D31: 43559 | E31: 9118.6 | F31: 11674 | G31: 2128.6
B32: Profit/Loss From Continuing Operations | C32: 27234 | D32: 43559 | E32: 9118.6 | F32: 11674 | G32: 2128.6
B33: Profit/Loss For The Period | C33: 27234 | D33: 43559 | E33: 9118.6 | F33: 11674 | G33: 2128.6
B34: OTHER ADDITIONAL INFORMATION
B35: EARNINGS PER SHARE
B36: Basic EPS (Rs.) | C36: 65.62 | D36: 119.44 | E36: 17.24 | F36: 43.11 | G36: 21.75
B37: Diluted EPS (Rs.) | C37: 65.56 | D37: 119.44 | E37: 17.19 | F37: 43.02 | G37: 21.69

Sheet Valuation Multiples
B2: Company Name | C2: Stock Price (current) | D2: EPS | E2: P/E | F2: Book Value | G2: P/B | H2: EV/EBITDA | I2: EV/Sales
B3: Infosys | C3: 1857.45 | D3: 65.62 | E3: 24.18 | F3: 195.6 | G3: 8.11 | H3: 15.67 | I3: 4.76
B4: TCS | C4: 4270.85 | D4: 119.44 | E4: 31.75 | F4: 199.23 | G4: 19.24 | H4: 22.17 | I4: 6.91
B5: Wipro | C5: 577.85 | D5: 17.24 | E5: 22.13 | F5: 110.59 | G5: 3.45 | H5: 17.06 | I5: 3.76
B6: HCL Tech | C6: 1848.05 | D6: 43.11 | E6: 19.85 | F6: 145.38 | G6: 5.88 | H6: 22.92 | I6: 8.55
B7: Tech Mahindra | C7: 1712.3 | D7: 21.75 | E7: 50.73 | F7: 237.19 | G7: 4.65 | H7: 33.26 | I7: 2.87
B8: Average | E8: =AVERAGE(E3:E7) -> 29.728 | G8: =AVERAGE(G3:G7) -> 8.266
B9: Median | E9: =MEDIAN(E3:E7) -> 24.18 | G9: =MEDIAN((G3:G7)) -> 5.88
B11: Calculations
B12: P/E Method (using Average)
B13: Average P/E | C13: 29.728
B14: Implied Stock Price (P/E) | C14: =65.62*29.728 -> 1950.7514
B16: P/B Method (using Average)
B17: Average P/B = 8.266 | C17: 8.266
B18: Implied Stock Price (P/B) | C18: =195.6*8.266 -> 1616.8296
B20: EV/EBITDA Method (using Average)
B21: Average EV/EBITDA | C21: 15.67
B22: Implied Stock Price (EV/EBITDA) | C22: =15.67*15.67 -> 245.5489
B24: EV/Sales Method (using Average)
B25: Average EV/Sales = 4.76 | C25: 4.76
B26: Implied Stock Price (EV/Sales) | C26: =4.76*4.76 -> 22.6576

Sheet Buyback Decision 
B2: Assess Buyback Decision for Infosys
B4: Method | C4: Implied Stock Price (₹) | D4: Current Stock Price (₹) | E4: Difference (₹) | F4: Interpretation
B5: P/E Method (using Average) | C5: 1950.75 | D5: 1857.45 | E5: 93.3 | F5: Slightly undervalued
B6: P/B Method (using Average) | C6: 1616.83 | D6: 1857.45 | E6: -240.62 | F6: Overvalued
B7: EV/EBITDA Method (using Average) | C7: 245.55 | D7: 1857.45 | E7: -1611.9 | F7: Overvalued
B8: EV/Sales Method (using Average) | C8: 22.66 | D8: 1857.45 | E8: -1834.79 | F8: Overvalued
